2021-09-24 16:39:12 Start downloading process. Time is 2021-09-24-16:39:12
2021-09-24 16:39:12 Directories created for 2017.
2021-09-24 16:39:12 Links created.
2021-09-24 16:39:12 Start downloading files.
2021-09-24 16:54:49 Download finished.
2021-09-24 16:54:49 Downloaded CSV files available in ROOT/drive/raw_data/lodes/2017.
2021-09-24 16:54:49 Directories created for 2018.
2021-09-24 16:54:49 Links created.
2021-09-24 16:54:49 Start downloading files.
2021-09-24 17:10:22 There was an error. See details below:
2021-09-24 17:10:22 None: Max retries exceeded with url: /data/lodes/LODES7/mt/wac/mt_wac_SE01_JT05_2018.csv.gz (Caused by None)
multiprocessing.pool.RemoteTraceback: 
"""
Traceback (most recent call last):
  File "C:\ProgramData\Anaconda3\lib\site-packages\urllib3\connection.py", line 159, in _new_conn
    conn = connection.create_connection(
  File "C:\ProgramData\Anaconda3\lib\site-packages\urllib3\util\connection.py", line 84, in create_connection
    raise err
  File "C:\ProgramData\Anaconda3\lib\site-packages\urllib3\util\connection.py", line 74, in create_connection
    sock.connect(sa)
TimeoutError: [WinError 10060] A connection attempt failed because the connected party did not properly respond after a period of time, or established connection failed because connected host has failed to respond

During handling of the above exception, another exception occurred:

Traceback (most recent call last):
  File "C:\ProgramData\Anaconda3\lib\site-packages\urllib3\connectionpool.py", line 670, in urlopen
    httplib_response = self._make_request(
  File "C:\ProgramData\Anaconda3\lib\site-packages\urllib3\connectionpool.py", line 381, in _make_request
    self._validate_conn(conn)
  File "C:\ProgramData\Anaconda3\lib\site-packages\urllib3\connectionpool.py", line 976, in _validate_conn
    conn.connect()
  File "C:\ProgramData\Anaconda3\lib\site-packages\urllib3\connection.py", line 308, in connect
    conn = self._new_conn()
  File "C:\ProgramData\Anaconda3\lib\site-packages\urllib3\connection.py", line 171, in _new_conn
    raise NewConnectionError(
urllib3.exceptions.NewConnectionError: <urllib3.connection.HTTPSConnection object at 0x00000268B7EF5790>: Failed to establish a new connection: [WinError 10060] A connection attempt failed because the connected party did not properly respond after a period of time, or established connection failed because connected host has failed to respond

During handling of the above exception, another exception occurred:

Traceback (most recent call last):
  File "C:\ProgramData\Anaconda3\lib\site-packages\requests\adapters.py", line 439, in send
    resp = conn.urlopen(
  File "C:\ProgramData\Anaconda3\lib\site-packages\urllib3\connectionpool.py", line 724, in urlopen
    retries = retries.increment(
  File "C:\ProgramData\Anaconda3\lib\site-packages\urllib3\util\retry.py", line 439, in increment
    raise MaxRetryError(_pool, url, error or ResponseError(cause))
urllib3.exceptions.MaxRetryError: HTTPSConnectionPool(host='lehd.ces.census.gov', port=443): Max retries exceeded with url: /data/lodes/LODES7/mt/wac/mt_wac_SE01_JT05_2018.csv.gz (Caused by NewConnectionError('<urllib3.connection.HTTPSConnection object at 0x00000268B7EF5790>: Failed to establish a new connection: [WinError 10060] A connection attempt failed because the connected party did not properly respond after a period of time, or established connection failed because connected host has failed to respond'))

During handling of the above exception, another exception occurred:

Traceback (most recent call last):
  File "C:\ProgramData\Anaconda3\lib\multiprocessing\pool.py", line 125, in worker
    result = (True, func(*args, **kwds))
  File "C:\ProgramData\Anaconda3\lib\multiprocessing\pool.py", line 48, in mapstar
    return list(map(*args))
  File "C:\Users\shermo\Documents\GitHub\min_wage_rent\raw\lodes\code\build.py", line 120, in download_file
    r = requests.get(url, stream = True)
  File "C:\ProgramData\Anaconda3\lib\site-packages\requests\api.py", line 76, in get
    return request('get', url, params=params, **kwargs)
  File "C:\ProgramData\Anaconda3\lib\site-packages\requests\api.py", line 61, in request
    return session.request(method=method, url=url, **kwargs)
  File "C:\ProgramData\Anaconda3\lib\site-packages\requests\sessions.py", line 530, in request
    resp = self.send(prep, **send_kwargs)
  File "C:\ProgramData\Anaconda3\lib\site-packages\requests\sessions.py", line 643, in send
    r = adapter.send(request, **kwargs)
  File "C:\ProgramData\Anaconda3\lib\site-packages\requests\adapters.py", line 516, in send
    raise ConnectionError(e, request=request)
requests.exceptions.ConnectionError: HTTPSConnectionPool(host='lehd.ces.census.gov', port=443): Max retries exceeded with url: /data/lodes/LODES7/mt/wac/mt_wac_SE01_JT05_2018.csv.gz (Caused by NewConnectionError('<urllib3.connection.HTTPSConnection object at 0x00000268B7EF5790>: Failed to establish a new connection: [WinError 10060] A connection attempt failed because the connected party did not properly respond after a period of time, or established connection failed because connected host has failed to respond'))
"""

The above exception was the direct cause of the following exception:

Traceback (most recent call last):
  File ".\build.py", line 198, in <module>
    process_files(data_types, states, year, logger, work_segs, work_types,
  File ".\build.py", line 61, in process_files
    downloaded_files_all = p.map(download_file, download_args)
  File "C:\ProgramData\Anaconda3\lib\multiprocessing\pool.py", line 364, in map
    return self._map_async(func, iterable, mapstar, chunksize).get()
  File "C:\ProgramData\Anaconda3\lib\multiprocessing\pool.py", line 771, in get
    raise self._value
requests.exceptions.ConnectionError: None: Max retries exceeded with url: /data/lodes/LODES7/mt/wac/mt_wac_SE01_JT05_2018.csv.gz (Caused by None)
